Workbook

Sheet Inputs
A1: VALMO | SLIDE 10 TEST, KPIs AND SCALE | INPUTS
A2: Hardcoded inputs are blue. Derived calculations are black. Values marked as planning assumptions should be replaced with measured pilot results before scale decisions.
A4: A. DICE CASE INPUTS
A5: Input | B5: Value | C5: Units | D5: Type | E5: Source / note | F5: Deck use | G5: Editable | H5: Owner
A6: Baseline RTO rate | B6: 0.17 | C6: % | D6: Case input | E6: DICE case pack | F6: Problem baseline | G6: No | H6: Operations
A7: COD share | B7: 0.8 | C7: % of orders | D7: Case input | E7: DICE case pack | F7: RTO mix | G7: No | H7: Operations
A8: COD RTO rate | B8: 0.2 | C8: % of COD orders | D8: Case input | E8: DICE case pack | F8: RTO mix | G8: No | H8: Operations
A9: Prepaid RTO rate | B9: 0.05 | C9: % of prepaid orders | D9: Case input | E9: DICE case pack | F9: RTO mix | G9: No | H9: Operations
A10: Forward logistics cost | B10: 50 | C10: ₹ / shipped order | D10: Case input | E10: DICE case pack | F10: Economic baseline | G10: No | H10: Finance
A11: Reverse logistics cost | B11: 120 | C11: ₹ / RTO | D11: Case input | E11: DICE case pack | F11: Economic hurdle | G11: No | H11: Finance
A12: Total failed-order logistics cost | B12: =B10+B11 -> 170 | C12: ₹ / RTO | D12: Derived | E12: Forward + reverse | F12: Economic engine | G12: No | H12: Finance
A13: Baseline cost / successful delivered order | B13: =(B10+B6*B11)/(1-B6) -> 84.819277 | C13: ₹ / success | D13: Derived | E13: Forward cost + expected reverse cost, divided by success rate | F13: North Star baseline | G13: No | H13: Finance
A14: Orders per normalized block | B14: 1000000 | C14: orders | D14: Scenario | E14: Normalized modelling unit used for scale case | F14: Scale bridge | G14: Yes | H14: Model
A15: Months in year | B15: 12 | C15: months | D15: Assumption | E15: Calendar assumption | F15: Annualisation | G15: No | H15: Model
A17: B. PILOT PLANNING INPUTS
A18: Input | B18: Value | C18: Units | D18: Purpose | E18: Status | F18: Source / note | G18: Editable | H18: Primary decision
A19: Q1 RTO improvement | B19: 0.01 | C19: pp | D19: Prove | E19: Planning assumption | F19: Carryover from Slide 9 model | G19: Yes | H19: Does prevention create positive contribution?
A20: Q2 RTO improvement | B20: 0.025 | C20: pp | D20: Optimise | E20: Planning assumption | F20: Carryover from Slide 9 model | G20: Yes | H20: Which segments work?
A21: Q3 RTO improvement | B21: 0.04 | C21: pp | D21: Expand | E21: Planning assumption | F21: Carryover from Slide 9 model | G21: Yes | H21: Can the model scale?
A22: Q4 RTO improvement | B22: 0.05 | C22: pp | D22: Scale | E22: Planning assumption | F22: Carryover from Slide 9 model | G22: Yes | H22: Does the run-rate remain positive?
A23: Q1 intervention spend | B23: 0.5 | C23: ₹ / order | D23: Blended cost | E23: Planning assumption | F23: Carryover from Slide 9 model | G23: Yes | H23: Cost discipline
A24: Q2 intervention spend | B24: 0.75 | C24: ₹ / order | D24: Blended cost | E24: Planning assumption | F24: Carryover from Slide 9 model | G24: Yes | H24: Cost discipline
A25: Q3 intervention spend | B25: 1 | C25: ₹ / order | D25: Blended cost | E25: Planning assumption | F25: Carryover from Slide 9 model | G25: Yes | H25: Cost discipline
A26: Q4 intervention spend | B26: 1.25 | C26: ₹ / order | D26: Blended cost | E26: Planning assumption | F26: Carryover from Slide 9 model | G26: Yes | H26: Cost discipline
A27: AI call cost | B27: 5 | C27: ₹ / action | D27: Worked example | E27: Planning assumption | F27: Slide 9 worked example | G27: Yes | H27: Break-even save rate
A28: Assisted call test orders | B28: 10000 | C28: orders | D28: Worked example | E28: Planning assumption | F28: Slide 9 worked example | G28: Yes | H28: Illustrative test size
A29: Assumed assisted-call save rate | B29: 0.06 | C29: % | D29: Worked example | E29: Planning assumption | F29: Slide 9 worked example | G29: Yes | H29: Illustrative outcome
A30: Rider premium offered | B30: 20 | C30: ₹ / qualifying order | D30: Solution 2 | E30: Planning assumption | F30: Slide 7 rider economics | G30: Yes | H30: Premium below expected value
A31: Rural protection cost | B31: 15 | C31: ₹ / protected order | D31: Solution 3 | E31: Planning assumption | F31: Slide 9 rider/rural economics | G31: Yes | H31: Protection value

Sheet Test_Maths
A1: VALMO | EXPERIMENT MATHS | BASELINE VS CONTROL VS TREATMENT
A2: Use matched control and treatment populations. Incremental RTO impact is measured against the control, not against a raw before/after comparison.
A4: A. FOUR TESTING TRACKS
A5: Track | B5: Control orders | C5: Treatment orders | D5: Control RTO rate | E5: Treatment RTO rate | F5: Incremental RTO reduction | G5: Incremental RTO avoided | H5: Value avoided | I5: Treatment spend | J5: Net value | K5: Cost / RTO avoided | L5: Economic gate | M5: Primary question
A6: Urban | B6: 10000 | C6: 10000 | D6: 0.17 | E6: 0.16 | F6: =D6-E6 -> 0.01 | G6: =B6*F6 -> 100 | H6: =G6*Inputs!$B$11 -> 12000 | I6: 50000 | J6: =H6-I6 -> -38000 | K6: =I6/G6 -> 500 | L6: =IF(K6<Inputs!$B$11,"PASS","FAIL") -> FAIL | M6: Does committed second-attempt scheduling improve delivery?
A7: Rural | B7: 10000 | C7: 10000 | D7: 0.17 | E7: 0.145 | F7: =D7-E7 -> 0.025 | G7: =B7*F7 -> 250 | H7: =G7*Inputs!$B$11 -> 30000 | I7: 75000 | J7: =H7-I7 -> -45000 | K7: =I7/G7 -> 300 | L7: =IF(K7<Inputs!$B$11,"PASS","FAIL") -> FAIL | M7: Does intent confirmation plus destination enrichment reduce rural RTO?
A8: Rider | B8: 10000 | C8: 10000 | D8: 0.17 | E8: 0.15 | F8: =D8-E8 -> 0.02 | G8: =B8*F8 -> 200 | H8: =G8*Inputs!$B$11 -> 24000 | I8: 75000 | J8: =H8-I8 -> -51000 | K8: =I8/G8 -> 375 | L8: =IF(K8<Inputs!$B$11,"PASS","FAIL") -> FAIL | M8: Does difficulty-adjusted incentive improve successful delivery without leakage?
A9: Recovery | B9: 10000 | C9: 10000 | D9: 0.17 | E9: 0.12 | F9: =D9-E9 -> 0.05 | G9: =B9*F9 -> 500 | H9: =G9*Inputs!$B$11 -> 60000 | I9: 150000 | J9: =H9-I9 -> -90000 | K9: =I9/G9 -> 300 | L9: =IF(K9<Inputs!$B$11,"PASS","FAIL") -> FAIL | M9: Does local recovery create positive net value after recovery costs?
A11: B. TEST METRICS AND EQUATIONS
A12: Metric | B12: Formula | C12: Worked example | D12: Units | E12: Why it matters | F12: Source / note | G12: Slide placement | H12: Owner
A13: RTO rate | B13: RTO orders ÷ shipped orders | C13: 1,700 ÷ 10,000 = 17.0% | D13: % | E13: Core failure metric | F13: DICE case pack | G13: KPI panel | H13: Operations
A14: Incremental RTO reduction | B14: Control RTO − Treatment RTO | C14: 17.0% − 16.0% = 1.0pp | D14: pp | E14: Causal impact | F14: Pilot method | G14: Experimental principle | H14: Operations
A15: RTOs avoided | B15: Control orders × incremental reduction | C15: 10,000 × 1.0% = 100 | D15: orders | E15: Benefit volume | F15: Derived | G15: Test result | H15: Operations
A16: Gross reverse cost avoided | B16: RTOs avoided × ₹120 | C16: 100 × ₹120 = ₹12,000 | D16: ₹ | E16: Economic value | F16: Deck economics | G16: Economic gate | H16: Finance
A17: Intervention spend | B17: Treatment orders × cost / order | C17: 10,000 × ₹5 = ₹50,000 | D17: ₹ | E17: Incremental investment | F17: Pilot input | G17: Economic gate | H17: Finance
A18: Net value | B18: Gross value avoided − spend | C18: ₹72,000 − ₹50,000 = ₹22,000 | D18: ₹ | E18: Contribution created | F18: Derived | G18: Economic gate | H18: Finance
A19: Cost / RTO avoided | B19: Spend ÷ RTOs avoided | C19: ₹50,000 ÷ 600 = ₹83.3 | D19: ₹ / RTO | E19: Primary scale hurdle | F19: Slide 9 | G19: Scale gate | H19: Finance
A20: North star | B20: Total delivery + intervention + recovery costs ÷ successful deliveries | C20: Calculated in North_Star_Maths | D20: ₹ / success | E20: Prevents cheap RTO reduction at the expense of delivered-order economics | F20: Slide 10 logic | G20: North Star | H20: Finance / Ops

Sheet North_Star_Maths
A1: VALMO | NORTH STAR | COST PER SUCCESSFUL DELIVERED ORDER
A2: North star includes forward delivery cost, expected reverse logistics burden and intervention spend. Lower is better, provided customer, rider and SLA guardrails also hold.
A4: A. NORTH STAR EVOLUTION
A5: Metric | B5: Baseline | C5: Q1 Prove | D5: Q2 Optimise | E5: Q3 Expand | F5: Q4 Scale | G5: Unit | H5: Direction
A6: RTO rate | B6: =Inputs!B6 -> 0.17 | C6: =Inputs!B6-Inputs!B19 -> 0.16 | D6: =Inputs!B6-Inputs!B20 -> 0.145 | E6: =Inputs!B6-Inputs!B21 -> 0.13 | F6: =Inputs!B6-Inputs!B22 -> 0.12 | G6: % | H6: ↓
A7: Successful delivery rate | B7: =1-B6 -> 0.83 | C7: =1-C6 -> 0.84 | D7: =1-D6 -> 0.855 | E7: =1-E6 -> 0.87 | F7: =1-F6 -> 0.88 | G7: % | H7: ↑
A8: Logistics cost / shipped order | B8: =Inputs!$B$10+B6*Inputs!$B$11 -> 70.4 | C8: =Inputs!$B$10+C6*Inputs!$B$11 -> 69.2 | D8: =Inputs!$B$10+D6*Inputs!$B$11 -> 67.4 | E8: =Inputs!$B$10+E6*Inputs!$B$11 -> 65.6 | F8: =Inputs!$B$10+F6*Inputs!$B$11 -> 64.4 | G8: ₹ / order | H8: ↓
A9: Intervention spend / shipped order | B9: 0 | C9: =Inputs!B23 -> 0.5 | D9: =Inputs!B24 -> 0.75 | E9: =Inputs!B25 -> 1 | F9: =Inputs!B26 -> 1.25 | G9: ₹ / order | H9: ↓
A10: Cost / successful delivered order | B10: =(B8+B9)/B7 -> 84.819277 | C10: =(C8+C9)/C7 -> 82.97619 | D10: =(D8+D9)/D7 -> 79.707602 | E10: =(E8+E9)/E7 -> 76.551724 | F10: =(F8+F9)/F7 -> 74.602273 | G10: ₹ / success | H10: ↓
A11: Change vs baseline | B11: - | C11: =($B$10-C10)/$B$10 -> 0.021729573 | D11: =($B$10-D10)/$B$10 -> 0.060265484 | E11: =($B$10-E10)/$B$10 -> 0.097472571 | F11: =($B$10-F10)/$B$10 -> 0.12045616 | G11: % | H11: ↑
A13: B. NORMALIZED 12-MONTH FINANCIAL BRIDGE
A14: Metric | B14: Q1 / Prove | C14: Q2 / Optimise | D14: Q3 / Expand | E14: Q4 / Scale | F14: FY total | G14: Units | H14: Formula / logic
A15: Modelled shipped orders | B15: =Inputs!$B$14 -> 1000000 | C15: =Inputs!$B$14 -> 1000000 | D15: =Inputs!$B$14 -> 1000000 | E15: =Inputs!$B$14 -> 1000000 | F15: =SUM(B15:E15) -> 4000000 | G15: orders | H15: 1M per quarter
A16: RTO improvement | B16: =Inputs!B19 -> 0.01 | C16: =Inputs!B20 -> 0.025 | D16: =Inputs!B21 -> 0.04 | E16: =Inputs!B22 -> 0.05 | G16: pp | H16: Inputs
A17: Gross reverse cost savings | B17: =B15*B16*Inputs!$B$11 -> 1200000 | C17: =C15*C16*Inputs!$B$11 -> 3000000 | D17: =D15*D16*Inputs!$B$11 -> 4800000 | E17: =E15*E16*Inputs!$B$11 -> 6000000 | F17: =SUM(B17:E17) -> 15000000 | G17: ₹ | H17: orders × improvement × ₹120
A18: Intervention spend | B18: =B15*1000000*Inputs!B23 -> 500000000000 | C18: =C15*1000000*Inputs!B24 -> 750000000000 | D18: =D15*1000000*Inputs!B25 -> 1000000000000 | E18: =E15*1000000*Inputs!B26 -> 1250000000000 | F18: =SUM(B18:E18) -> 3500000000000 | G18: ₹ | H18: orders × spend / order
A19: Net value created | B19: =B17-B18 -> -499998800000 | C19: =C17-C18 -> -749997000000 | D19: =D17-D18 -> -999995200000 | E19: =E17-E18 -> -1249994000000 | F19: =SUM(B19:E19) -> -3499985000000 | G19: ₹ | H19: gross savings − intervention spend

Sheet Intervention_Econ
A1: VALMO | INTERVENTION ECONOMICS | BREAK-EVEN AND HURDLES
A2: Pre-dispatch prevention can protect the full ₹170 failed-order logistics cost. Post-dispatch rescue uses the ₹120 reverse-cost hurdle. This distinction is retained throughout the model.
A4: A. INTERVENTION BREAK-EVEN LADDER
A5: Intervention | B5: Stage | C5: Cost / action (₹) | D5: Value at stake (₹) | E5: Break-even save rate | F5: Net value at 10% save (₹) | G5: Cost / RTO avoided at 10% (₹) | H5: Use
A6: WhatsApp / SMS | B6: Pre-dispatch | C6: 2 | D6: 170 | E6: =C6/D6 -> 0.011764706 | F6: =10%*D6-C6 -> 15 | G6: =C6/10% -> 20 | H6: Broad low-cost test
A7: AI call | B7: Pre-dispatch | C7: 5 | D7: 170 | E7: =C7/D7 -> 0.029411765 | F7: =10%*D7-C7 -> 12 | G7: =C7/10% -> 50 | H7: High reachability risk
A8: Human-assisted call | B8: Pre-dispatch | C8: 10 | D8: 170 | E8: =C8/D8 -> 0.058823529 | F8: =10%*D8-C8 -> 7 | G8: =C8/10% -> 100 | H8: Higher-touch segments
A9: Rider reattempt | B9: Post-dispatch | C9: 20 | D9: 120 | E9: =C9/D9 -> 0.16666667 | F9: =10%*D9-C9 -> -8 | G9: =C9/10% -> 200 | H9: Only where success uplift is material
A10: Nearby-hub reroute | B10: Post-dispatch | C10: 30 | D10: 120 | E10: =C10/D10 -> 0.25 | F10: =10%*D10-C10 -> -18 | G10: =C10/10% -> 300 | H10: Use where allocation is the issue
A11: Rural Connection Shield | B11: Post-dispatch | D11: 120 | E11: =C11/D11 -> 0 | F11: =10%*D11-C11 -> 12 | G11: =C11/10% -> 0 | H11: Pilot-calibrated protection cost
A12: Flash Store recovery | B12: Recovery | C12: 15 | D12: 120 | E12: =C12/D12 -> 0.125 | F12: =10%*D12-C12 -> -3 | G12: =C12/10% -> 150 | H12: Positive only if recovery clears handling hurdle
A14: B. ASSISTED CALL WORKED EXAMPLE
A15: Step | B15: Value | C15: Units | D15: Formula | E15: Interpretation | F15: Source | G15: Status | H15: Slide use
A16: Targeted first-NDR orders | B16: =Inputs!B28 -> 10000 | C16: orders | D16: Input | E16: Test population | F16: Slide 9 model | G16: Planning | H16: Hero calculation
A17: AI call cost / order | B17: =Inputs!B27 -> 5 | C17: ₹ / order | D17: Input | E17: Intervention spend | F17: Slide 9 model | G17: Planning | H17: Hero calculation
A18: Assumed save rate | B18: =Inputs!B29 -> 0.06 | C18: % | D18: Input | E18: Illustrative outcome | F18: Slide 9 model | G18: Planning | H18: Hero calculation
A19: RTOs avoided | B19: =B16*B18 -> 600 | C19: orders | D19: Orders × save rate | E19: Incremental impact | F19: Derived | G19: Planning | H19: Hero calculation
A20: Intervention spend | B20: =B16*B17 -> 50000 | C20: ₹ | D20: Orders × cost | E20: Incremental investment | F20: Derived | G20: Planning | H20: Hero calculation
A21: Reverse cost avoided | B21: =B19*Inputs!B11 -> 72000 | C21: ₹ | D21: RTOs avoided × ₹120 | E21: Gross value | F21: Derived | G21: Planning | H21: Hero calculation
A22: Net value | B22: =B21-B20 -> 22000 | C22: ₹ | D22: Gross value − spend | E22: Contribution | F22: Derived | G22: Planning | H22: Hero calculation
A23: Cost / RTO avoided | B23: =B20/B19 -> 83.333333 | C23: ₹ / RTO | D23: Spend ÷ avoided RTO | E23: Compare with ₹120 hurdle | F23: Derived | G23: Planning | H23: Scale gate
A25: C. SAVE-RATE SENSITIVITY
A26: Save rate | B26: RTOs avoided / 10K | C26: Value saved @ ₹120 | D26: Intervention cost | E26: Net value | F26: Cost / RTO avoided
A27: 0.02 | B27: =A27*Inputs!B28 -> 200 | C27: =B27*Inputs!B11 -> 24000 | D27: =Inputs!B27*Inputs!B28 -> 50000 | E27: =C27-D27 -> -26000 | F27: =D27/B27 -> 250
A28: 0.05 | B28: =A28*Inputs!B28 -> 500 | C28: =B28*Inputs!B11 -> 60000 | D28: =Inputs!B27*Inputs!B28 -> 50000 | E28: =C28-D28 -> 10000 | F28: =D28/B28 -> 100
A29: 0.1 | B29: =A29*Inputs!B28 -> 1000 | C29: =B29*Inputs!B11 -> 120000 | D29: =Inputs!B27*Inputs!B28 -> 50000 | E29: =C29-D29 -> 70000 | F29: =D29/B29 -> 50
A30: 0.15 | B30: =A30*Inputs!B28 -> 1500 | C30: =B30*Inputs!B11 -> 180000 | D30: =Inputs!B27*Inputs!B28 -> 50000 | E30: =C30-D30 -> 130000 | F30: =D30/B30 -> 33.333333
A31: 0.2 | B31: =A31*Inputs!B28 -> 2000 | C31: =B31*Inputs!B11 -> 240000 | D31: =Inputs!B27*Inputs!B28 -> 50000 | E31: =C31-D31 -> 190000 | F31: =D31/B31 -> 25
A33: D. RIDER PREMIUM CEILING
A34: Scenario | B34: P(save) | C34: Expected value / qualifying order | D34: Premium offered | E34: Headroom / (shortfall) | F34: Decision | G34: Rule
A35: Conservative | B35: 0.2 | C35: =B35*Inputs!B11 -> 24 | D35: =Inputs!B30 -> 20 | E35: =C35-D35 -> 4 | F35: =IF(E35>=0,"Within ceiling","Above ceiling") -> Within ceiling | G35: Premium ≤ expected value
A36: Base | B36: 0.3 | C36: =B36*Inputs!B11 -> 36 | D36: =Inputs!B30 -> 20 | E36: =C36-D36 -> 16 | F36: =IF(E36>=0,"Within ceiling","Above ceiling") -> Within ceiling | G36: Premium ≤ expected value
A37: Strong | B37: 0.4 | C37: =B37*Inputs!B11 -> 48 | D37: =Inputs!B30 -> 20 | E37: =C37-D37 -> 28 | F37: =IF(E37>=0,"Within ceiling","Above ceiling") -> Within ceiling | G37: Premium ≤ expected value
A38: High | B38: 0.5 | C38: =B38*Inputs!B11 -> 60 | D38: =Inputs!B30 -> 20 | E38: =C38-D38 -> 40 | F38: =IF(E38>=0,"Within ceiling","Above ceiling") -> Within ceiling | G38: Premium ≤ expected value
A39: Theoretical ceiling @ 30% | B39: 0.3 | C39: =B39*Inputs!B11 -> 36 | D39: =B39*Inputs!B11 -> 36 | E39: =C39-D39 -> 0 | F39: =IF(E39>=0,"Within ceiling","Above ceiling") -> Within ceiling | G39: P(save) × ₹120

Sheet FlashStore_Econ
A1: VALMO | FLASH STORE | LOCAL RECOVERY ECONOMICS
A2: Recovery value combines reverse logistics avoided with recovered local sales, less seller discount, fulfilment, handling, payment and expected second RTO.
A4: A. NET RECOVERY VALUE PER RECOVERED PARCEL
A5: Line item | B5: Value | C5: Type | D5: Formula / logic | E5: Source / note
A6: Recovered sale revenue | B6: 280 | C6: Benefit | D6: Input | E6: Slide 8 illustrative example
A7: Seller approved discount | B7: 65 | C7: Cost | D7: Input | E7: Seller-set recovery price
A8: Local fulfilment cost | B8: 30 | C8: Cost | D8: Input | E8: Local delivery / fulfilment
A9: Handling cost | B9: 15 | C9: Cost | D9: Input | E9: Kirana / recovery handling
A10: Payment processing | B10: 5 | C10: Cost | D10: Input | E10: Payment cost
A11: Expected second RTO cost | B11: 12 | C11: Cost | D11: Input | E11: Expected leakage after recovery
A12: Reverse logistics avoided | B12: 120 | C12: Benefit | D12: Input | E12: ₹120 reverse hurdle
A13: Net recovery value | B13: =B6-B7-B8-B9-B10-B11+B12 -> 273 | C13: Derived | D13: Benefits − costs | E13: Economic result
A15: B. RECOVERY RATE SENSITIVITY
A16: Recovery rate | B16: Eligible parcels | C16: Recovered parcels | D16: Net recovery value / parcel | E16: Total net value | F16: Recovery cost | G16: Net value
A17: 0.05 | B17: 10000 | C17: =A17*B17 -> 500 | D17: =$B$13 -> 273 | E17: =C17*D17 -> 136500 | F17: =C17*B9 -> 7500 | G17: =E17-F17 -> 129000
A18: 0.125 | B18: 10000 | C18: =A18*B18 -> 1250 | D18: =$B$13 -> 273 | E18: =C18*D18 -> 341250 | F18: =C18*B9 -> 18750 | G18: =E18-F18 -> 322500
A19: 0.2 | B19: 10000 | C19: =A19*B19 -> 2000 | D19: =$B$13 -> 273 | E19: =C19*D19 -> 546000 | F19: =C19*B9 -> 30000 | G19: =E19-F19 -> 516000
A20: 0.3 | B20: 10000 | C20: =A20*B20 -> 3000 | D20: =$B$13 -> 273 | E20: =C20*D20 -> 819000 | F20: =C20*B9 -> 45000 | G20: =E20-F20 -> 774000
A21: 0.4 | B21: 10000 | C21: =A21*B21 -> 4000 | D21: =$B$13 -> 273 | E21: =C21*D21 -> 1092000 | F21: =C21*B9 -> 60000 | G21: =E21-F21 -> 1032000

Sheet Partner_Econ
A1: VALMO | PARTNER SCORECARD | INCENTIVE AND SAVINGS MATH
A2: Partner governance economics use avoided RTOs as the value pool. Incentive payout is kept below the value created so the governance layer remains contribution-positive.
A4: A. 100-ORDER VALUE CREATION
A5: Scenario | B5: Orders | C5: RTOs recovered / 100 | D5: Value / RTO | E5: Gross value created | F5: Operating cost | G5: Net value | H5: Net value / order
A6: Full capture | B6: 100 | C6: 1.04 | D6: =Inputs!B11 -> 120 | E6: =C6*D6 -> 124.8 | F6: 35 | G6: =E6-F6 -> 89.8 | H6: =G6/B6 -> 0.898
A7: 50% capture | B7: 100 | C7: =C6*50% -> 0.52 | D7: =D6 -> 120 | E7: =C7*D7 -> 62.4 | F7: 35 | G7: =E7-F7 -> 27.4 | H7: =G7/B7 -> 0.274
A8: Partner example | B8: 2000 | C8: =B8*3% -> 60 | D8: =Inputs!B11 -> 120 | E8: =C8*D8 -> 7200 | F8: =E8*25% -> 1800 | G8: =E8-F8 -> 5400 | H8: =F8/B8 -> 0.9
A9: Elite bonus pool | B9: =B8 -> 2000 | C9: =C8 -> 60 | E9: =E8 -> 7200 | F9: =E8*25% -> 1800 | G9: =E9-F9 -> 5400 | H9: =F9/B9 -> 0.9
A10: Bonus / delivery | B10: =B8 -> 2000 | F10: =F9 -> 1800 | H10: =F10/B10 -> 0.9

Sheet KPI_Maths
A1: VALMO | KPI CALCULATION ENGINE | NORTH STAR + STAKEHOLDERS
A2: Every KPI is tied to a decision. Daily operational metrics can diagnose movement, while weekly economic metrics determine whether an intervention can scale.
A4: A. KPI CALCULATIONS
A5: Dimension | B5: KPI | C5: Numerator | D5: Denominator | E5: Formula | F5: Target direction | G5: Cadence | H5: Scale gate | I5: Owner | J5: Current value
A6: North Star | B6: Cost / successful delivered order | E6: (forward + expected reverse + intervention + recovery costs) ÷ successful deliveries | F6: ↓ | G6: Weekly | H6: Must improve | I6: Finance / Ops | J6: =North_Star_Maths!F10 -> 74.602273
A7: Customer | B7: RTO rate | E7: RTO orders ÷ shipped orders | F7: ↓ | G7: Daily | H7: Improve vs control | I7: Operations | J7: =North_Star_Maths!F6 -> 0.12
A8: Customer | B8: NDR → delivery conversion | E8: Delivered after first failure ÷ first-NDR orders | F8: ↑ | G8: Daily | H8: Improve vs control | I8: Ops / Product | J8: =0 -> 0
A9: Customer | B9: Reschedule completion | E9: Completed slots ÷ accepted slots | F9: ↑ | G9: Daily | H9: No deterioration | I9: Product | J9: =0 -> 0
A10: Rider | B10: Verified attempt rate | E10: Attempts with GPS + timestamp + contact + reason code ÷ total attempts | F10: ↑ | G10: Daily | H10: No deterioration | I10: Partner Ops | J10: =0 -> 0
A11: Rider | B11: ₹ / productive hour | E11: Rider earnings ÷ productive hours | F11: ≥ baseline | G11: Weekly | H11: No deterioration | I11: Partner Ops | J11: =0 -> 0
A12: Network | B12: Wrong-hub rate | E12: Wrong-hub orders ÷ shipped orders | F12: ↓ | G12: Daily | H12: Stable or better | I12: Network | J12: =0 -> 0
A13: Recovery | B13: Second-RTO rate | E13: Second RTO ÷ recovered parcels | F13: ↓ | G13: Daily | H13: No worsening | I13: Recovery Ops | J13: =0 -> 0
A15: B. NORTH STAR RECONCILIATION
A16: Component | B16: Baseline | C16: Q1 | D16: Q2 | E16: Q3 | F16: Q4 | G16: Units | H16: Logic
A17: Forward cost / shipped order | B17: =Inputs!B10 -> 50 | C17: =Inputs!B10 -> 50 | D17: =Inputs!B10 -> 50 | E17: =Inputs!B10 -> 50 | F17: =Inputs!B10 -> 50 | G17: ₹ / order | H17: ₹50
A18: Expected reverse cost / shipped order | B18: =North_Star_Maths!B6*Inputs!B11 -> 20.4 | C18: =North_Star_Maths!C6*Inputs!B11 -> 19.2 | D18: =North_Star_Maths!D6*Inputs!B11 -> 17.4 | E18: =North_Star_Maths!E6*Inputs!B11 -> 15.6 | F18: =North_Star_Maths!F6*Inputs!B11 -> 14.4 | G18: ₹ / order | H18: RTO rate × ₹120
A19: Intervention spend / shipped order | B19: 0 | C19: =Inputs!B23 -> 0.5 | D19: =Inputs!B24 -> 0.75 | E19: =Inputs!B25 -> 1 | F19: =Inputs!B26 -> 1.25 | G19: ₹ / order | H19: Planning input
A20: Total delivery cost / shipped order | B20: =B17+B18+B19 -> 70.4 | C20: =C17+C18+C19 -> 69.7 | D20: =D17+D18+D19 -> 68.15 | E20: =E17+E18+E19 -> 66.6 | F20: =F17+F18+F19 -> 65.65 | G20: ₹ / order | H20: Forward + reverse + intervention
A21: Successful delivery rate | B21: =1-North_Star_Maths!B6 -> 0.83 | C21: =1-North_Star_Maths!C6 -> 0.84 | D21: =1-North_Star_Maths!D6 -> 0.855 | E21: =1-North_Star_Maths!E6 -> 0.87 | F21: =1-North_Star_Maths!F6 -> 0.88 | G21: % | H21: 1 − RTO rate
A22: Cost / successful delivered order | B22: =B20/B21 -> 84.819277 | C22: =C20/C21 -> 82.97619 | D22: =D20/D21 -> 79.707602 | E22: =E20/E21 -> 76.551724 | F22: =F20/F21 -> 74.602273 | G22: ₹ / success | H22: Total delivery cost ÷ success rate
A23: Change vs baseline | B23: - | C23: =($B$22-C22)/$B$22 -> 0.021729573 | D23: =($B$22-D22)/$B$22 -> 0.060265484 | E23: =($B$22-E22)/$B$22 -> 0.097472571 | F23: =($B$22-F22)/$B$22 -> 0.12045616 | G23: % | H23: Baseline less scenario, divided by baseline

Sheet Pilot_Roadmap
A1: VALMO | 30 TO 60 TO 90 DAY PILOT | PROVE, OPTIMISE, SCALE
A2: The pilot stages are designed to isolate causal impact first, then optimise segment fit, then integrate the winning logic into existing Valmo workflows.
A4: A. PILOT STAGES
A5: Stage | B5: Timing | C5: Objective | D5: Target pool | E5: Interventions | F5: Design | G5: Output | H5: Decision | I5: Primary KPI | J5: Economic test | K5: Guardrails
A6: PROVE | B6: 0 to 30 days | C6: Measure incremental impact | D6: First-NDR + COD-heavy + specific failure reasons | E6: Customer confirmation / AI call | F6: Control vs treatment, randomise within eligible segment | G6: Validated uplift by cause | H6: Continue only if contribution-positive | I6: RTO vs control | J6: Cost / RTO avoided < ₹120 | K6: Rider, CX and SLA protected
A7: OPTIMISE | B7: 31 to 60 days | C7: Improve segment fit | D7: Urban, rural, rider, recovery clusters | E7: Appointment, rural intent, difficulty premium, verified attempt, selected recovery | F7: Segment by geography, pincode, distance and failure cause | G7: Winning segment playbook | H7: Expand only where unit economics hold | I7: NDR to delivery; verified attempt; recovery rate | J7: Positive contribution in winning segments | K7: No material operational complexity
A8: SCALE / MODIFY / STOP | B8: 61 to 90 days | C8: Integrate winners into workflows | D8: Proven segments and partner clusters | E8: Allocation + risk + rider + recovery integration | F8: Controlled rollout with scale gates | G8: Repeatable operating model | H8: Scale, modify or stop by gate | I8: North star cost / success | J8: Positive net value and gate compliance | K8: No deterioration in customer, rider, speed or operations
A10: B. TARGET PILOT POOL
A11: Filter | B11: Purpose | C11: Include | D11: Exclude | E11: Reason | F11: Owner
A12: First NDR | B12: Earliest rescue point | C12: First failed attempt | D12: Multiple prior attempts | E12: Cleanest causal test | F12: Operations
A13: COD-heavy / high-risk | B13: Concentrate likely RTO exposure | C13: COD orders, high-risk signals | D13: Low-risk prepaid segments | E13: Higher signal density | F13: Operations
A14: High RTO / difficult segment | B14: Target economics where intervention matters | C14: Distance, pincode, category, partner risk | D14: Very low-risk orders | E14: Avoid broad low-yield testing | F14: Network
A15: Specific failure reason | B15: Match intervention to cause | C15: Availability, address, intent, payment | D15: Unknown reason | E15: Prevents one-size-fits-all treatment | F15: Product
A16: Matched controls | B16: Prevent allocation bias | C16: Same reason + geography + order mix | D16: Non-comparable controls | E16: Improves interpretability | F16: Analytics
A18: C. RANDOMISATION AND CONTROL METHOD
A19: Track | B19: Randomisation method | C19: Control | D19: Treatment | E19: Unit of assignment | F19: Primary measure | G19: Guardrail | H19: Interpretation
A20: Urban | B20: Order-level randomisation among eligible orders | C20: Normal NDR process | D20: Appointment-based reattempt | E20: Order | F20: Incremental RTO reduction | G20: CSAT and SLA | H20: Treatment wins if RTO drops without CX or speed damage
A21: Rural | B21: Order-level randomisation where operationally feasible | C21: Current COD / delivery journey | D21: Intent confirmation + destination enrichment | E21: Order | F21: RTO reduction by segment | G21: Distance and serviceability | H21: Use geography-specific treatment effects
A22: Rider | B22: Rider or cluster-level test to prevent incentive spillover | C22: Existing rider economics | D22: Difficulty premium + verified attempt + quality-gated bonus | E22: Rider / cluster | F22: Successful deliveries / rider-hour | G22: ₹ / productive hour | H22: Pay only when productivity and quality hold
A23: Recovery | B23: Eligible parcels randomly assigned to matched control / treatment | C23: Eligible parcel follows normal RTO | D23: Eligible parcel enters recovery flow | E23: Parcel | F23: Recovery net value | G23: Second RTO and dwell | H23: Recover only when local value is positive
A25: D. RICE PRIORITISATION
A26: Intervention | B26: Reach | C26: Impact | D26: Confidence | E26: Effort | F26: RICE score | G26: Priority | H26: Reason
A27: AI call / assisted contact | B27: 5 | C27: 4 | D27: 4 | E27: 2 | F27: =B27*C27*D27/E27 -> 40 | G27: =RANK(F27,$F$27:$F$31,0) -> 1 | H27: High reach, low implementation effort
A28: Reschedule / appointment | B28: 4 | C28: 4 | D28: 4 | E28: 2 | F28: =B28*C28*D28/E28 -> 32 | G28: =RANK(F28,$F$27:$F$31,0) -> 2 | H28: Directly tests customer availability
A29: Rider incentive, difficulty-adjusted | B29: 4 | C29: 4 | D29: 3 | E29: 3 | F29: =B29*C29*D29/E29 -> 16 | G29: =RANK(F29,$F$27:$F$31,0) -> 3 | H29: Potentially large impact but needs behaviour controls
A30: Rural Connection Shield | B30: 3 | C30: 4 | D30: 3 | E30: 3 | F30: =B30*C30*D30/E30 -> 12 | G30: =RANK(F30,$F$27:$F$31,0) -> 4 | H30: Targeted rural value where connection loss is costly
A31: Kirana / Flash Store recovery | B31: 2 | C31: 4 | D31: 3 | E31: 4 | F31: =B31*C31*D31/E31 -> 6 | G31: =RANK(F31,$F$27:$F$31,0) -> 5 | H31: High value per success but narrower eligible pool

Sheet Risk_Gates
A1: VALMO | RISKS, GUARDRAILS AND SCALE GATES
A2: Every intervention has a corresponding failure mode, monitoring KPI and stop or modify condition. No scale decision is based on RTO alone.
A4: A. RISK TO GUARDRAIL
A5: Risk | B5: Failure mode | C5: Guardrail | D5: KPI | E5: Stop / modify signal | F5: Owner | G5: Priority | H5: Status
A6: Rider gaming | B6: Fake or instant attempt marking | C6: GPS + timestamp + minimum dwell + contact event + reason code | D6: Verified-attempt rate | E6: Anomaly or complaint increase | F6: Partner Ops | G6: High | H6: Monitor
A7: Cherry-picking | B7: Difficult orders avoided | C7: Difficulty score, allocation checked first, targeted premium | D7: Acceptance by difficulty band | E7: High-risk acceptance gap | F7: Network / Partner Ops | G7: High | H7: Monitor
A8: Node inventory buildup | B8: Recovery node fills and parcel ages | C8: Dynamic capacity, stop routing when full | D8: Dwell time / utilisation | E8: Dwell or loss worsens | F8: Recovery Ops | G8: Medium | H8: Monitor
A9: Seller resistance | B9: Low opt-in to reallocation | C9: Seller opt-in + price floor / discount band | D9: Opt-in / satisfaction | E9: Opt-in too low | F9: Seller Ops | G9: Medium | H9: Monitor
A10: Customer fatigue | B10: Too many contacts | C10: Reason-specific action, stop after clear refusal | D10: Complaint / opt-out rate | E10: Complaint increase | F10: CX / Product | G10: Medium | H10: Monitor
A11: Second RTO | B11: Recovered sale fails again | C11: Prepaid / high-intent buyer + eligibility gate | D11: Second-RTO rate | E11: Second-RTO worsens | F11: Recovery Ops | G11: High | H11: Monitor
A13: B. SCALE GATE
A14: Gate | B14: Measure | C14: Scale condition | D14: Why it matters | E14: Owner | F14: Status
A15: Economics | B15: Cost / RTO avoided | C15: < ₹120 | D15: Contribution must exceed reverse-cost hurdle | E15: Finance | F15: PENDING PILOT
A16: RTO | B16: Incremental RTO reduction | C16: Meaningful reduction vs control | D16: Confirms causal impact | E16: Operations | F16: PENDING PILOT
A17: Rider | B17: ₹ / productive hour | C17: ≥ baseline | D17: Protects partner economics | E17: Partner Ops | F17: PENDING PILOT
A18: Customer | B18: Complaints / CSAT | C18: No material deterioration | D18: Protects customer experience | E18: CX | F18: PENDING PILOT
A19: Speed | B19: TAT / SLA | C19: No material increase | D19: Prevents hidden service degradation | E19: Operations | F19: PENDING PILOT
A20: Operations / Recovery | B20: Wrong-hub, distance, damage, second RTO | C20: Stable or improved; positive recovery economics | D20: Prevents scale-induced leakage | E20: Ops / Recovery | F20: PENDING PILOT
A22: C. 12-MONTH OPERATING LOOP
A23: Stage | B23: Decision question | C23: What scales | D23: Evidence required | E23: Primary KPI | F23: Dependency
A24: Predict | B24: Where is RTO risk concentrated? | C24: Existing risk signals as inputs | D24: Calibration and lift by segment | E24: RTO by segment | F24: Data availability
A25: Prevent | B25: Can the failure be avoided economically? | C25: Address, LMDC, intent and rider actions | D25: Positive incremental economics | E25: Cost / RTO avoided | F25: Correct allocation
A26: Intercept | B26: What is the cheapest next best action? | C26: Reason-specific decision layer | D26: Control vs treatment effect | E26: NDR to delivery | F26: Reason codes
A27: Recover | B27: Can parcel value be preserved? | C27: Kirana + seller-authorized reallocation | D27: Positive unit economics | E27: Match / pickup / second RTO | F27: Seller + legal readiness

Sheet Math_Guide
A1: VALMO | SLIDE 10 MATH GUIDE
A2: Use this sheet as the audit trail when presenting the slide. Every headline number should trace back to a case input or a clearly labelled planning assumption.
A4: A. CORE FORMULAS
A5: Calculation | B5: Equation | C5: Worked example | D5: Interpretation | E5: Source / status | F5: Slide use
A6: Blended RTO rate | B6: COD share × COD RTO + prepaid share × prepaid RTO | C6: 80% × 20% + 20% × 5% = 17.0% | D6: Baseline RTO | E6: DICE case input | F6: Slides 2 and 10
A7: Reverse cost / shipped order | B7: RTO rate × ₹120 | C7: 17% × ₹120 = ₹20.40 | D7: Expected reverse burden per shipped order | E7: Derived from case | F7: Slides 2 and 10
A8: Failed-order logistics cost | B8: ₹50 + ₹120 | C8: ₹170 | D8: Forward + reverse cost at stake | E8: DICE case input | F8: Slide 9 link
A9: Baseline cost / successful delivery | B9: (₹50 + RTO × ₹120) ÷ (1 − RTO) | C9: 70.4 ÷ 83% = ₹84.82 | D9: North-star baseline | E9: Derived from case | F9: Slide 10
A10: Incremental RTO reduction | B10: Control RTO − treatment RTO | C10: 17% − 16% = 1.0pp | D10: Causal treatment effect | E10: Pilot methodology | F10: Slide 10
A11: RTOs avoided | B11: Control orders × incremental reduction | C11: 10,000 × 1% = 100 | D11: Incremental impact volume | E11: Derived | F11: Slide 10
A12: Reverse cost avoided | B12: RTOs avoided × ₹120 | C12: 600 × ₹120 = ₹72,000 | D12: Gross reverse-cost value | E12: Derived | F12: Slide 9 / 10
A13: Intervention spend | B13: Treatment orders × intervention cost / order | C13: 10,000 × ₹5 = ₹50,000 | D13: Incremental investment | E13: Illustrative model | F13: Slide 10
A14: Net value | B14: Gross value avoided − intervention spend | C14: ₹72,000 − ₹50,000 = ₹22,000 | D14: Contribution before second-order effects | E14: Derived | F14: Slide 9 / 10
A15: Cost / RTO avoided | B15: Intervention spend ÷ RTOs avoided | C15: ₹50,000 ÷ 600 = ₹83.3 | D15: Primary economics gate | E15: Derived | F15: Slide 9 / 10
A16: Rider premium ceiling | B16: P(save) × ₹120 | C16: 30% × ₹120 = ₹36 | D16: Maximum theoretical premium | E16: Architecture logic | F16: Slide 9
... A18: RICE | B18: Reach × Impact × Confidence ÷ Effort | C18: 5 × 4 × 4 ÷ 2 = 40 | D18: Prioritisation score | E18: Planning framework | F18: Slide 10
A20: B. 12-MONTH SCALE MATH
A21: Calculation | B21: Equation | C21: Example | D21: Interpretation | E21: Status | F21: Caveat
A22: Gross savings / quarter | B22: Orders × RTO improvement × ₹120 | C22: 1M × 1pp × ₹120 = ₹12 lakh | D22: Gross reverse-cost savings | E22: Scenario | F22: Normalized volume
A23: Intervention spend / quarter | B23: Orders × spend / order | C23: 1M × ₹0.50 = ₹5 lakh | D23: Investment | E23: Scenario | F23: Replace with actual spend
A24: Net value / quarter | B24: Gross savings − intervention spend | C24: ₹12 lakh − ₹5 lakh = ₹7 lakh | D24: Contribution | E24: Scenario | F24: Before second-order effects
A25: Cost / RTO avoided | B25: Spend ÷ incremental RTOs avoided | C25: ₹5 lakh ÷ 10,000 = ₹50 | D25: Unit economics | E25: Scenario | F25: Must remain < ₹120
A26: Annualized Q4 net value | B26: Monthly net × 12 | C26: ₹47.5 lakh × 12 = ₹5.7 Cr | D26: Run-rate illustration | E26: Scenario | F26: Not a forecast
A27: North-star change | B27: (Baseline − Scenario) ÷ Baseline | C27: (84.82 − 74.60) ÷ 84.82 = 12.0% | D27: Efficiency improvement | E27: Scenario | F27: Includes intervention spend
A28: Scale decision | B28: All gates pass | C28: Economics + RTO + Rider + Customer + Speed + Operations | D28: Prevents premature scaling | E28: Rule | F28: Requires pilot evidence

Sheet Slide10_Dashboard
A1: 10. TEST + KPIs + 30 TO 60 TO 90 + SCALE
A2: TEST WHAT WORKS. SCALE ONLY WHAT CREATES NET VALUE.
A3: Every intervention must be evaluated on incremental RTO reduction, economic contribution, rider economics, customer experience, speed and operational stability.
A5: A. EXPERIMENTAL PRINCIPLE | TEST → LEARN → PROVE ECONOMICS → SCALE
A6: BASELINE | B6: CONTROL | C6: VS | D6: TREATMENT | E6: INCREMENTAL IMPACT | F6: ECONOMIC VALUE | G6: GUARDRAILS | H6: DECISION
A7: Recent comparable orders | B7: Current Valmo process | D7: Failure-specific intervention | E7: RTO treatment vs control | F7: ₹120 reverse hurdle + intervention cost | G7: Rider + CX + speed + operations | H7: Scale only if all gates pass
A8: Same eligible segment and order mix | B8: Randomised within eligible pool | D8: Reason-specific treatment | E8: NDR → delivery conversion | F8: Cost / RTO avoided | G8: No material deterioration | H8: Modify or stop if any hard gate fails
A10: B. TESTING TRACKS | DO NOT RUN ONE GIANT PILOT
A11: URBAN | B11: Control | C11: Treatment | D11: Key question | E11: RURAL | F11: Control | G11: Treatment | H11: Key question | I11: RIDER | J11: Control | K11: Treatment | L11: Key question | M11: RECOVERY | N11: Control
A12: Customer unavailability | B12: Normal NDR | C12: Appointment reattempt | D12: Does a committed slot improve delivery? | E12: Intent + reachability | F12: Current COD / delivery journey | G12: Intent confirmation + destination enrichment | H12: Does confirming intent reduce avoidable RTO? | I12: Difficulty-adjusted incentive | J12: Existing rider economics | K12: Difficulty premium + verified attempt + quality-gated bonus | L12: Does incentive improve success without payout leakage? | M12: Local recovery | N12: Eligible parcel follows normal RTO
M13: Eligible parcel enters recovery flow
L14: Key question: does local recovery create positive net value?
A16: C. TARGET PILOT POOL + RANDOMISATION
A17: Target pool | B17: Include | C17: Exclude | D17: Why | E17: Randomisation | F17: Unit | G17: Key measure | H17: Control integrity
A18: First NDR | B18: First failed attempt | C18: Multiple prior attempts | D18: Clean causal test | E18: Order-level | F18: Order | G18: Incremental RTO reduction | H18: Matched order mix
A19: COD-heavy / high-risk | B19: COD, high-risk signals | C19: Low-risk prepaid | D19: Higher RTO signal density | E19: Within eligible pool | F19: Order | G19: RTO vs control | H19: Matched geography
A20: High RTO / difficult | B20: Distance, pincode, category | C20: Very low-risk orders | D20: Focus on economic opportunity | E20: Within segment | F20: Order | G20: Cost / RTO avoided | H20: Matched difficulty
A21: Specific failure reason | B21: Availability, address, intent, payment | C21: Unknown cause | D21: Match treatment to cause | E21: Within reason | F21: Order | G21: Cause-specific uplift | H21: Same failure taxonomy
A22: Rider / recovery | B22: Eligible rider clusters or parcels | C22: Non-eligible | D22: Avoid spillover | E22: Cluster / parcel randomisation | F22: Rider or parcel | G22: Quality + net value | H22: Matched partner / inventory
A24: D. NORTH STAR KPI FRAMEWORK
A25: NORTH STAR | B25: CUSTOMER KPIs | C25: RIDER KPIs | D25: NETWORK KPIs | E25: RECOVERY KPIs | F25: Definition | G25: Direction | H25: Cadence | I25: Scale gate | J25: Owner
A26: ₹ COST / SUCCESSFUL DELIVERED ORDER | B26: RTO rate | C26: Verified-attempt rate | D26: Wrong-hub rate | E26: Recovery rate | F26: Total delivery + intervention + recovery costs ÷ successful deliveries | G26: ↓ | H26: Weekly | I26: Must improve | J26: Finance / Ops
B27: NDR → delivery conversion | C27: ₹ / productive hour | D27: Address correction rate | E27: ₹ reverse cost avoided | F27: Delivered after first failure ÷ first-NDR orders | G27: ↑ | H27: Daily | I27: Improve vs control | J27: Operations
B28: Reschedule completion | C28: Acceptance / productivity | D28: Distance / route efficiency | E28: Second-RTO rate | F28: Second-RTO ÷ recovered parcels | G28: ↑ / ↓ | H28: Daily | I28: No deterioration | J28: Product / Ops
B29: CSAT / complaints | C29: Rider complaints | D29: Cost / successful order | E29: Holding / damage loss | F29: Stakeholder protection metrics | G29: Mixed | H29: Weekly | I29: No deterioration | J29: CX / Partner Ops
A31: E. 30 TO 60 TO 90 DAY ROADMAP
A32: 0 TO 30 DAYS | PROVE | B32: 31 TO 60 DAYS | OPTIMISE | C32: 61 TO 90 DAYS | SCALE / MODIFY / STOP | D32: Pilot decision
A33: Run controlled pilots Focus on first-NDR COD-heavy Build failure reason taxonomy Instrument calls, GPS, attempt quality Measure intervention economics | B33: Refine targeting by segment Check LMDC fit and partner coordination Add difficulty-adjusted rider economics Verified attempt protocol Test selected recovery nodes Slice by cause, distance and pincode | C33: Integrate winning logic into allocation and workflows Expand by proven category / geography / partner cluster Scale rider incentive to eligible segments Scale recovery selectively Validate operational complexity | D33: PROVE contribution Then OPTIMISE fit Then SCALE only where gates hold
A34: Evidence: RTO lift, cost / RTO avoided, rider/CX/SLA protection | B34: Evidence: segment economics, recovery conversion, partner fit | C34: Evidence: repeatable contribution + guardrails | D34: Decision: continue, modify or stop
A35: Question: does the intervention create positive economics? | B35: Question: where does it actually work? | C35: Question: can it survive real operations?
A37: F. SCALE GATE | ALL MUST HOLD
A38: Economics | B38: RTO | C38: Rider | D38: Customer | E38: Speed | F38: Operations | G38: Recovery | H38: Stop / modify trigger | I38: Status | J38: Owner
A39: Cost / RTO avoided < ₹120 | B39: Meaningful reduction vs control | C39: ₹ / productive hour ≥ baseline | D39: Complaints / CSAT not materially worse | E39: TAT / SLA not materially worse | F39: Wrong-hub, distance and cost stable or better | G39: Positive recovery economics | H39: Any gate fails | I39: PENDING PILOT | J39: Relevant owner
A40: Includes intervention spend | B40: Control group required | C40: No payout leakage | D40: No intervention fatigue | E40: No hidden service degradation | F40: No material complexity, fraud or damage | G40: Second-RTO controlled | H40: MODIFY or STOP
A41: Scale only after measured evidence
A45: G. RICE PRIORITISATION
A46: Intervention | B46: Reach | C46: Impact | D46: Confidence | E46: Effort | F46: RICE score | G46: Priority
A47: AI call / assisted contact | B47: 5 | C47: 4 | D47: 4 | E47: 2 | F47: =B47*C47*D47/E47 -> 40 | G47: =RANK(F47,$F$47:$F$51,0) -> 1
A48: Reschedule / appointment | B48: 4 | C48: 4 | D48: 4 | E48: 2 | F48: =B48*C48*D48/E48 -> 32 | G48: =RANK(F48,$F$47:$F$51,0) -> 2
A49: Rider incentive, difficulty-adjusted | B49: 4 | C49: 4 | D49: 3 | E49: 3 | F49: =B49*C49*D49/E49 -> 16 | G49: =RANK(F49,$F$47:$F$51,0) -> 3
...
